Workbook

Sheet Sheet6
A3: Row Labels | B3: Count of OrderID | C3: Sum of Difference | D3: Sum of Billing Amount | E3: Sum of Expected charges
A4: Correctly Charged | B4: 41 | C4: 0 | D4: 1737.4 | E4: 1737.4
A5: Over Charged | B5: 359 | C5: 31560.8 | D5: 47567.2 | E5: 16006.4
A6: Grand Total | B6: 400 | C6: 31560.8 | D6: 49304.6 | E6: 17743.8

Sheet Order Report
A1: Order ID | B1: OrderID | C1: SKU (Product Code) | D1: Order Qty | E1: Product weight | F1: Weight per order (g) | G1: Weight per order (Kg) | H1: Weight slab | I1: Zone | J1: Type of shipment | K1: Fixed_Charges | L1: Additional_Charges | M1: No_of_Extra_slabs | N1: Expected charges | O1: Billing Amount | P1: Difference | Q1: Charge Type
A2: 2001827036 | B2: =Table1[[#This Row],[Order ID]]*1 -> 2001827036 | C2: 8904223818706 | D2: 1 | E2: =_xlfn.XLOOKUP(Table1[[#This Row],[SKU (Product Code)]],'SKU Master'!A:A,'SKU Master'!B:B) -> 127 | F2: =Table1[[#This Row],[Product weight]]*Table1[[#This Row],[Order Qty]] -> 127 | G2: =Table1[[#This Row],[Weight per order (g)]]/1000 -> 0.127 | H2: =CEILING(Table1[[#This Row],[Weight per order (Kg)]],0.5) -> 0.5 | I2: =_xlfn.XLOOKUP(Table1[[#This Row],[OrderID]],'Courier company invoice'!B:B,'Courier company invoice'!F:F) -> b | J2: =_xlfn.XLOOKUP(Table1[[#This Row],[OrderID]],Table2[Order ID],Table2[Type of Shipment],"Not Found") -> Forward charges | K2: =INDEX(Sheet1[],1,MATCH("fwd_"&Table1[[#This Row],[Zone]]&"_fixed",Sheet1[#Headers],0)) -> 33 | L2: =INDEX(Sheet1[],1,MATCH("fwd_"&Table1[[#This Row],[Zone]]&"_additional",Sheet1[#Headers],0)) -> 28.3 | M2: =(Table1[[#This Row],[Weight slab]]-0.5)/0.5 -> 0 | N2: =Table1[[#This Row],[Fixed_Charges]]+Table1[[#This Row],[No_of_Extra_slabs]]*Table1[[#This Row],[Additional_Charges]] -> 33 | O2: =_xlfn.XLOOKUP(Table1[[#This Row],[OrderID]],'Courier company invoice'!B:B,'Courier company invoice'!H:H) -> 117.9 | P2: =Table1[[#This Row],[Billing Amount]]-Table1[[#This Row],[Expected charges]] -> 84.9 | Q2: {=_xlfn.IFS(Table1[[#This Row],[Billing Amount]]>Table1[[#This Row],[Expected charges]],"Over Charged",Table1[[#This Row],[Billing Amount]]<Table1[[#This Row],[Expected charges]],"Under Charged",Table1[[#This Row],[Billing Amount]]=Table1[[#This Row],[Expected charges]],"Correctly Charged")} -> Over Charged
A3: 2001827036 | B3: =Table1[[#This Row],[Order ID]]*1 -> 2001827036 | C3: 8904223819093 | D3: 1 | E3: =_xlfn.XLOOKUP(Table1[[#This Row],[SKU (Product Code)]],'SKU Master'!A:A,'SKU Master'!B:B) -> 150 | F3: =Table1[[#This Row],[Product weight]]*Table1[[#This Row],[Order Qty]] -> 150 | G3: =Table1[[#This Row],[Weight per order (g)]]/1000 -> 0.15 | H3: =CEILING(Table1[[#This Row],[Weight per order (Kg)]],0.5) -> 0.5 | I3: =_xlfn.XLOOKUP(Table1[[#This Row],[OrderID]],'Courier company invoice'!B:B,'Courier company invoice'!F:F) -> b | J3: =_xlfn.XLOOKUP(Table1[[#This Row],[OrderID]],Table2[Order ID],Table2[Type of Shipment],"Not Found") -> Forward charges | K3: =INDEX(Sheet1[],1,MATCH("fwd_"&Table1[[#This Row],[Zone]]&"_fixed",Sheet1[#Headers],0)) -> 33 | L3: =INDEX(Sheet1[],1,MATCH("fwd_"&Table1[[#This Row],[Zone]]&"_additional",Sheet1[#Headers],0)) -> 28.3 | M3: =(Table1[[#This Row],[Weight slab]]-0.5)/0.5 -> 0 | N3: =Table1[[#This Row],[Fixed_Charges]]+Table1[[#This Row],[No_of_Extra_slabs]]*Table1[[#This Row],[Additional_Charges]] -> 33 | O3: =_xlfn.XLOOKUP(Table1[[#This Row],[OrderID]],'Courier company invoice'!B:B,'Courier company invoice'!H:H) -> 117.9 | P3: =Table1[[#This Row],[Billing Amount]]-Table1[[#This Row],[Expected charges]] -> 84.9 | Q3: {=_xlfn.IFS(Table1[[#This Row],[Billing Amount]]>Table1[[#This Row],[Expected charges]],"Over Charged",Table1[[#This Row],[Billing Amount]]<Table1[[#This Row],[Expected charges]],"Under Charged",Table1[[#This Row],[Billing Amount]]=Table1[[#This Row],[Expected charges]],"Correctly Charged")} -> Over Charged
A4: 2001827036 | B4: =Table1[[#This Row],[Order ID]]*1 -> 2001827036 | C4: 8904223819109 | D4: 1 | E4: =_xlfn.XLOOKUP(Table1[[#This Row],[SKU (Product Code)]],'SKU Master'!A:A,'SKU Master'!B:B) -> 100 | F4: =Table1[[#This Row],[Product weight]]*Table1[[#This Row],[Order Qty]] -> 100 | G4: =Table1[[#This Row],[Weight per order (g)]]/1000 -> 0.1 | H4: =CEILING(Table1[[#This Row],[Weight per order (Kg)]],0.5) -> 0.5 | I4: =_xlfn.XLOOKUP(Table1[[#This Row],[OrderID]],'Courier company invoice'!B:B,'Courier company invoice'!F:F) -> b | J4: =_xlfn.XLOOKUP(Table1[[#This Row],[OrderID]],Table2[Order ID],Table2[Type of Shipment],"Not Found") -> Forward charges | K4: =INDEX(Sheet1[],1,MATCH("fwd_"&Table1[[#This Row],[Zone]]&"_fixed",Sheet1[#Headers],0)) -> 33 | L4: =INDEX(Sheet1[],1,MATCH("fwd_"&Table1[[#This Row],[Zone]]&"_additional",Sheet1[#Headers],0)) -> 28.3 | M4: =(Table1[[#This Row],[Weight slab]]-0.5)/0.5 -> 0 | N4: =Table1[[#This Row],[Fixed_Charges]]+Table1[[#This Row],[No_of_Extra_slabs]]*Table1[[#This Row],[Additional_Charges]] -> 33 | O4: =_xlfn.XLOOKUP(Table1[[#This Row],[OrderID]],'Courier company invoice'!B:B,'Courier company invoice'!H:H) -> 117.9 | P4: =Table1[[#This Row],[Billing Amount]]-Table1[[#This Row],[Expected charges]] -> 84.9 | Q4: {=_xlfn.IFS(Table1[[#This Row],[Billing Amount]]>Table1[[#This Row],[Expected charges]],"Over Charged",Table1[[#This Row],[Billing Amount]]<Table1[[#This Row],[Expected charges]],"Under Charged",Table1[[#This Row],[Billing Amount]]=Table1[[#This Row],[Expected charges]],"Correctly Charged")} -> Over Charged
A5: 2001827036 | B5: =Table1[[#This Row],[Order ID]]*1 -> 2001827036 | C5: 8904223818430 | D5: 1 | E5: =_xlfn.XLOOKUP(Table1[[#This Row],[SKU (Product Code)]],'SKU Master'!A:A,'SKU Master'!B:B) -> 165 | F5: =Table1[[#This Row],[Product weight]]*Table1[[#This Row],[Order Qty]] -> 165 | G5: =Table1[[#This Row],[Weight per order (g)]]/1000 -> 0.165 | H5: =CEILING(Table1[[#This Row],[Weight per order (Kg)]],0.5) -> 0.5 | I5: =_xlfn.XLOOKUP(Table1[[#This Row],[OrderID]],'Courier company invoice'!B:B,'Courier company invoice'!F:F) -> b | J5: =_xlfn.XLOOKUP(Table1[[#This Row],[OrderID]],Table2[Order ID],Table2[Type of Shipment],"Not Found") -> Forward charges | K5: =INDEX(Sheet1[],1,MATCH("fwd_"&Table1[[#This Row],[Zone]]&"_fixed",Sheet1[#Headers],0)) -> 33 | L5: =INDEX(Sheet1[],1,MATCH("fwd_"&Table1[[#This Row],[Zone]]&"_additional",Sheet1[#Headers],0)) -> 28.3 | M5: =(Table1[[#This Row],[Weight slab]]-0.5)/0.5 -> 0 | N5: =Table1[[#This Row],[Fixed_Charges]]+Table1[[#This Row],[No_of_Extra_slabs]]*Table1[[#This Row],[Additional_Charges]] -> 33 | O5: =_xlfn.XLOOKUP(Table1[[#This Row],[OrderID]],'Courier company invoice'!B:B,'Courier company invoice'!H:H) -> 117.9 | P5: =Table1[[#This Row],[Billing Amount]]-Table1[[#This Row],[Expected charges]] -> 84.9 | Q5: {=_xlfn.IFS(Table1[[#This Row],[Billing Amount]]>Table1[[#This Row],[Expected charges]],"Over Charged",Table1[[#This Row],[Billing Amount]]<Table1[[#This Row],[Expected charges]],"Under Charged",Table1[[#This Row],[Billing Amount]]=Table1[[#This Row],[Expected charges]],"Correctly Charged")} -> Over Charged
A6: 2001827036 | B6: =Table1[[#This Row],[Order ID]]*1 -> 2001827036 | C6: 8904223819277 | D6: 1 | E6: =_xlfn.XLOOKUP(Table1[[#This Row],[SKU (Product Code)]],'SKU Master'!A:A,'SKU Master'!B:B) -> 350 | F6: =Table1[[#This Row],[Product weight]]*Table1[[#This Row],[Order Qty]] -> 350 | G6: =Table1[[#This Row],[Weight per order (g)]]/1000 -> 0.35 | H6: =CEILING(Table1[[#This Row],[Weight per order (Kg)]],0.5) -> 0.5 | I6: =_xlfn.XLOOKUP(Table1[[#This Row],[OrderID]],'Courier company invoice'!B:B,'Courier company invoice'!F:F) -> b | J6: =_xlfn.XLOOKUP(Table1[[#This Row],[OrderID]],Table2[Order ID],Table2[Type of Shipment],"Not Found") -> Forward charges | K6: =INDEX(Sheet1[],1,MATCH("fwd_"&Table1[[#This Row],[Zone]]&"_fixed",Sheet1[#Headers],0)) -> 33 | L6: =INDEX(Sheet1[],1,MATCH("fwd_"&Table1[[#This Row],[Zone]]&"_additional",Sheet1[#Headers],0)) -> 28.3 | M6: =(Table1[[#This Row],[Weight slab]]-0.5)/0.5 -> 0 | N6: =Table1[[#This Row],[Fixed_Charges]]+Table1[[#This Row],[No_of_Extra_slabs]]*Table1[[#This Row],[Additional_Charges]] -> 33 | O6: =_xlfn.XLOOKUP(Table1[[#This Row],[OrderID]],'Courier company invoice'!B:B,'Courier company invoice'!H:H) -> 117.9 | P6: =Table1[[#This Row],[Billing Amount]]-Table1[[#This Row],[Expected charges]] -> 84.9 | Q6: {=_xlfn.IFS(Table1[[#This Row],[Billing Amount]]>Table1[[#This Row],[Expected charges]],"Over Charged",Table1[[#This Row],[Billing Amount]]<Table1[[#This Row],[Expected charges]],"Under Charged",Table1[[#This Row],[Billing Amount]]=Table1[[#This Row],[Expected charges]],"Correctly Charged")} -> Over Charged
A7: 2001827036 | B7: =Table1[[#This Row],[Order ID]]*1 -> 2001827036 | C7: GIFTBOX202002 | D7: 1 | E7: =_xlfn.XLOOKUP(Table1[[#This Row],[SKU (Product Code)]],'SKU Master'!A:A,'SKU Master'!B:B) -> 500 | F7: =Table1[[#This Row],[Product weight]]*Table1[[#This Row],[Order Qty]] -> 500 | G7: =Table1[[#This Row],[Weight per order (g)]]/1000 -> 0.5 | H7: =CEILING(Table1[[#This Row],[Weight per order (Kg)]],0.5) -> 0.5 | I7: =_xlfn.XLOOKUP(Table1[[#This Row],[OrderID]],'Courier company invoice'!B:B,'Courier company invoice'!F:F) -> b | J7: =_xlfn.XLOOKUP(Table1[[#This Row],[OrderID]],Table2[Order ID],Table2[Type of Shipment],"Not Found") -> Forward charges | K7: =INDEX(Sheet1[],1,MATCH("fwd_"&Table1[[#This Row],[Zone]]&"_fixed",Sheet1[#Headers],0)) -> 33 | L7: =INDEX(Sheet1[],1,MATCH("fwd_"&Table1[[#This Row],[Zone]]&"_additional",Sheet1[#Headers],0)) -> 28.3 | M7: =(Table1[[#This Row],[Weight slab]]-0.5)/0.5 -> 0 | N7: =Table1[[#This Row],[Fixed_Charges]]+Table1[[#This Row],[No_of_Extra_slabs]]*Table1[[#This Row],[Additional_Charges]] -> 33 | O7: =_xlfn.XLOOKUP(Table1[[#This Row],[OrderID]],'Courier company invoice'!B:B,'Courier company invoice'!H:H) -> 117.9 | P7: =Table1[[#This Row],[Billing Amount]]-Table1[[#This Row],[Expected charges]] -> 84.9 | Q7: {=_xlfn.IFS(Table1[[#This Row],[Billing Amount]]>Table1[[#This Row],[Expected charges]],"Over Charged",Table1[[#This Row],[Billing Amount]]<Table1[[#This Row],[Expected charges]],"Under Charged",Table1[[#This Row],[Billing Amount]]=Table1[[#This Row],[Expected charges]],"Correctly Charged")} -> Over Charged
A8: 2001827036 | B8: =Table1[[#This Row],[Order ID]]*1 -> 2001827036 | C8: 8904223818638 | D8: 2 | E8: =_xlfn.XLOOKUP(Table1[[#This Row],[SKU (Product Code)]],'SKU Master'!A:A,'SKU Master'!B:B) -> 137 | F8: =Table1[[#This Row],[Product weight]]*Table1[[#This Row],[Order Qty]] -> 274 | G8: =Table1[[#This Row],[Weight per order (g)]]/1000 -> 0.274 | H8: =CEILING(Table1[[#This Row],[Weight per order (Kg)]],0.5) -> 0.5 | I8: =_xlfn.XLOOKUP(Table1[[#This Row],[OrderID]],'Courier company invoice'!B:B,'Courier company invoice'!F:F) -> b | J8: =_xlfn.XLOOKUP(Table1[[#This Row],[OrderID]],Table2[Order ID],Table2[Type of Shipment],"Not Found") -> Forward charges | K8: =INDEX(Sheet1[],1,MATCH("fwd_"&Table1[[#This Row],[Zone]]&"_fixed",Sheet1[#Headers],0)) -> 33 | L8: =INDEX(Sheet1[],1,MATCH("fwd_"&Table1[[#This Row],[Zone]]&"_additional",Sheet1[#Headers],0)) -> 28.3 | M8: =(Table1[[#This Row],[Weight slab]]-0.5)/0.5 -> 0 | N8: =Table1[[#This Row],[Fixed_Charges]]+Table1[[#This Row],[No_of_Extra_slabs]]*Table1[[#This Row],[Additional_Charges]] -> 33 | O8: =_xlfn.XLOOKUP(Table1[[#This Row],[OrderID]],'Courier company invoice'!B:B,'Courier company invoice'!H:H) -> 117.9 | P8: =Table1[[#This Row],[Billing Amount]]-Table1[[#This Row],[Expected charges]] -> 84.9 | Q8: {=_xlfn.IFS(Table1[[#This Row],[Billing Amount]]>Table1[[#This Row],[Expected charges]],"Over Charged",Table1[[#This Row],[Billing Amount]]<Table1[[#This Row],[Expected charges]],"Under Charged",Table1[[#This Row],[Billing Amount]]=Table1[[#This Row],[Expected charges]],"Correctly Charged")} -> Over Charged
A9: 2001827036 | B9: =Table1[[#This Row],[Order ID]]*1 -> 2001827036 | C9: SACHETS001 | D9: 1 | E9: =_xlfn.XLOOKUP(Table1[[#This Row],[SKU (Product Code)]],'SKU Master'!A:A,'SKU Master'!B:B) -> 10 | F9: =Table1[[#This Row],[Product weight]]*Table1[[#This Row],[Order Qty]] -> 10 | G9: =Table1[[#This Row],[Weight per order (g)]]/1000 -> 0.01 | H9: =CEILING(Table1[[#This Row],[Weight per order (Kg)]],0.5) -> 0.5 | I9: =_xlfn.XLOOKUP(Table1[[#This Row],[OrderID]],'Courier company invoice'!B:B,'Courier company invoice'!F:F) -> b | J9: =_xlfn.XLOOKUP(Table1[[#This Row],[OrderID]],Table2[Order ID],Table2[Type of Shipment],"Not Found") -> Forward charges | K9: =INDEX(Sheet1[],1,MATCH("fwd_"&Table1[[#This Row],[Zone]]&"_fixed",Sheet1[#Headers],0)) -> 33 | L9: =INDEX(Sheet1[],1,MATCH("fwd_"&Table1[[#This Row],[Zone]]&"_additional",Sheet1[#Headers],0)) -> 28.3 | M9: =(Table1[[#This Row],[Weight slab]]-0.5)/0.5 -> 0 | N9: =Table1[[#This Row],[Fixed_Charges]]+Table1[[#This Row],[No_of_Extra_slabs]]*Table1[[#This Row],[Additional_Charges]] -> 33 | O9: =_xlfn.XLOOKUP(Table1[[#This Row],[OrderID]],'Courier company invoice'!B:B,'Courier company invoice'!H:H) -> 117.9 | P9: =Table1[[#This Row],[Billing Amount]]-Table1[[#This Row],[Expected charges]] -> 84.9 | Q9: {=_xlfn.IFS(Table1[[#This Row],[Billing Amount]]>Table1[[#This Row],[Expected charges]],"Over Charged",Table1[[#This Row],[Billing Amount]]<Table1[[#This Row],[Expected charges]],"Under Charged",Table1[[#This Row],[Billing Amount]]=Table1[[#This Row],[Expected charges]],"Correctly Charged")} -> Over Charged
A10: 2001825261 | B10: =Table1[[#This Row],[Order ID]]*1 -> 2001825261 | C10: 8904223819024 | D10: 4 | E10: =_xlfn.XLOOKUP(Table1[[#This Row],[SKU (Product Code)]],'SKU Master'!A:A,'SKU Master'!B:B) -> 112 | F10: =Table1[[#This Row],[Product weight]]*Table1[[#This Row],[Order Qty]] -> 448 | G10: =Table1[[#This Row],[Weight per order (g)]]/1000 -> 0.448 | H10: =CEILING(Table1[[#This Row],[Weight per order (Kg)]],0.5) -> 0.5 | I10: =_xlfn.XLOOKUP(Table1[[#This Row],[OrderID]],'Courier company invoice'!B:B,'Courier company invoice'!F:F) -> d | J10: =_xlfn.XLOOKUP(Table1[[#This Row],[OrderID]],Table2[Order ID],Table2[Type of Shipment],"Not Found") -> Forward and RTO charges | K10: =INDEX(Sheet1[],1,MATCH("fwd_"&Table1[[#This Row],[Zone]]&"_fixed",Sheet1[#Headers],0)) -> 45.4 | L10: =INDEX(Sheet1[],1,MATCH("fwd_"&Table1[[#This Row],[Zone]]&"_additional",Sheet1[#Headers],0)) -> 44.8 | M10: =(Table1[[#This Row],[Weight slab]]-0.5)/0.5 -> 0 | N10: =Table1[[#This Row],[Fixed_Charges]]+Table1[[#This Row],[No_of_Extra_slabs]]*Table1[[#This Row],[Additional_Charges]] -> 45.4 | O10: =_xlfn.XLOOKUP(Table1[[#This Row],[OrderID]],'Courier company invoice'!B:B,'Courier company invoice'!H:H) -> 345 | P10: =Table1[[#This Row],[Billing Amount]]-Table1[[#This Row],[Expected charges]] -> 299.6 | Q10: {=_xlfn.IFS(Table1[[#This Row],[Billing Amount]]>Table1[[#This Row],[Expected charges]],"Over Charged",Table1[[#This Row],[Billing Amount]]<Table1[[#This Row],[Expected charges]],"Under Charged",Table1[[#This Row],[Billing Amount]]=Table1[[#This Row],[Expected charges]],"Correctly Charged")} -> Over Charged
A11: 2001825261 | B11: =Table1[[#This Row],[Order ID]]*1 -> 2001825261 | C11: 8904223819291 | D11: 4 | E11: =_xlfn.XLOOKUP(Table1[[#This Row],[SKU (Product Code)]],'SKU Master'!A:A,'SKU Master'!B:B) -> 112 | F11: =Table1[[#This Row],[Product weight]]*Table1[[#This Row],[Order Qty]] -> 448 | G11: =Table1[[#This Row],[Weight per order (g)]]/1000 -> 0.448 | H11: =CEILING(Table1[[#This Row],[Weight per order (Kg)]],0.5) -> 0.5 | I11: =_xlfn.XLOOKUP(Table1[[#This Row],[OrderID]],'Courier company invoice'!B:B,'Courier company invoice'!F:F) -> d | J11: =_xlfn.XLOOKUP(Table1[[#This Row],[OrderID]],Table2[Order ID],Table2[Type of Shipment],"Not Found") -> Forward and RTO charges | K11: =INDEX(Sheet1[],1,MATCH("fwd_"&Table1[[#This Row],[Zone]]&"_fixed",Sheet1[#Headers],0)) -> 45.4 | L11: =INDEX(Sheet1[],1,MATCH("fwd_"&Table1[[#This Row],[Zone]]&"_additional",Sheet1[#Headers],0)) -> 44.8 | M11: =(Table1[[#This Row],[Weight slab]]-0.5)/0.5 -> 0 | N11: =Table1[[#This Row],[Fixed_Charges]]+Table1[[#This Row],[No_of_Extra_slabs]]*Table1[[#This Row],[Additional_Charges]] -> 45.4 | O11: =_xlfn.XLOOKUP(Table1[[#This Row],[OrderID]],'Courier company invoice'!B:B,'Courier company invoice'!H:H) -> 345 | P11: =Table1[[#This Row],[Billing Amount]]-Table1[[#This Row],[Expected charges]] -> 299.6 | Q11: {=_xlfn.IFS(Table1[[#This Row],[Billing Amount]]>Table1[[#This Row],[Expected charges]],"Over Charged",Table1[[#This Row],[Billing Amount]]<Table1[[#This Row],[Expected charges]],"Under Charged",Table1[[#This Row],[Billing Amount]]=Table1[[#This Row],[Expected charges]],"Correctly Charged")} -> Over Charged
A12: 2001825261 | B12: =Table1[[#This Row],[Order ID]]*1 -> 2001825261 | C12: 8904223818638 | D12: 3 | E12: =_xlfn.XLOOKUP(Table1[[#This Row],[SKU (Product Code)]],'SKU Master'!A:A,'SKU Master'!B:B) -> 137 | F12: =Table1[[#This Row],[Product weight]]*Table1[[#This Row],[Order Qty]] -> 411 | G12: =Table1[[#This Row],[Weight per order (g)]]/1000 -> 0.411 | H12: =CEILING(Table1[[#This Row],[Weight per order (Kg)]],0.5) -> 0.5 | I12: =_xlfn.XLOOKUP(Table1[[#This Row],[OrderID]],'Courier company invoice'!B:B,'Courier company invoice'!F:F) -> d | J12: =_xlfn.XLOOKUP(Table1[[#This Row],[OrderID]],Table2[Order ID],Table2[Type of Shipment],"Not Found") -> Forward and RTO charges | K12: =INDEX(Sheet1[],1,MATCH("fwd_"&Table1[[#This Row],[Zone]]&"_fixed",Sheet1[#Headers],0)) -> 45.4 | L12: =INDEX(Sheet1[],1,MATCH("fwd_"&Table1[[#This Row],[Zone]]&"_additional",Sheet1[#Headers],0)) -> 44.8 | M12: =(Table1[[#This Row],[Weight slab]]-0.5)/0.5 -> 0 | N12: =Table1[[#This Row],[Fixed_Charges]]+Table1[[#This Row],[No_of_Extra_slabs]]*Table1[[#This Row],[Additional_Charges]] -> 45.4 | O12: =_xlfn.XLOOKUP(Table1[[#This Row],[OrderID]],'Courier company invoice'!B:B,'Courier company invoice'!H:H) -> 345 | P12: =Table1[[#This Row],[Billing Amount]]-Table1[[#This Row],[Expected charges]] -> 299.6 | Q12: {=_xlfn.IFS(Table1[[#This Row],[Billing Amount]]>Table1[[#This Row],[Expected charges]],"Over Charged",Table1[[#This Row],[Billing Amount]]<Table1[[#This Row],[Expected charges]],"Under Charged",Table1[[#This Row],[Billing Amount]]=Table1[[#This Row],[Expected charges]],"Correctly Charged")} -> Over Charged
A13: 2001825261 | B13: =Table1[[#This Row],[Order ID]]*1 -> 2001825261 | C13: 8904223818669 | D13: 1 | E13: =_xlfn.XLOOKUP(Table1[[#This Row],[SKU (Product Code)]],'SKU Master'!A:A,'SKU Master'!B:B) -> 240 | F13: =Table1[[#This Row],[Product weight]]*Table1[[#This Row],[Order Qty]] -> 240 | G13: =Table1[[#This Row],[Weight per order (g)]]/1000 -> 0.24 | H13: =CEILING(Table1[[#This Row],[Weight per order (Kg)]],0.5) -> 0.5 | I13: =_xlfn.XLOOKUP(Table1[[#This Row],[OrderID]],'Courier company invoice'!B:B,'Courier company invoice'!F:F) -> d | J13: =_xlfn.XLOOKUP(Table1[[#This Row],[OrderID]],Table2[Order ID],Table2[Type of Shipment],"Not Found") -> Forward and RTO charges | K13: =INDEX(Sheet1[],1,MATCH("fwd_"&Table1[[#This Row],[Zone]]&"_fixed",Sheet1[#Headers],0)) -> 45.4 | L13: =INDEX(Sheet1[],1,MATCH("fwd_"&Table1[[#This Row],[Zone]]&"_additional",Sheet1[#Headers],0)) -> 44.8 | M13: =(Table1[[#This Row],[Weight slab]]-0.5)/0.5 -> 0 | N13: =Table1[[#This Row],[Fixed_Charges]]+Table1[[#This Row],[No_of_Extra_slabs]]*Table1[[#This Row],[Additional_Charges]] -> 45.4 | O13: =_xlfn.XLOOKUP(Table1[[#This Row],[OrderID]],'Courier company invoice'!B:B,'Courier company invoice'!H:H) -> 345 | P13: =Table1[[#This Row],[Billing Amount]]-Table1[[#This Row],[Expected charges]] -> 299.6 | Q13: {=_xlfn.IFS(Table1[[#This Row],[Billing Amount]]>Table1[[#This Row],[Expected charges]],"Over Charged",Table1[[#This Row],[Billing Amount]]<Table1[[#This Row],[Expected charges]],"Under Charged",Table1[[#This Row],[Billing Amount]]=Table1[[#This Row],[Expected charges]],"Correctly Charged")} -> Over Charged
A14: 2001825261 | B14: =Table1[[#This Row],[Order ID]]*1 -> 2001825261 | C14: SACHETS001 | D14: 1 | E14: =_xlfn.XLOOKUP(Table1[[#This Row],[SKU (Product Code)]],'SKU Master'!A:A,'SKU Master'!B:B) -> 10 | F14: =Table1[[#This Row],[Product weight]]*Table1[[#This Row],[Order Qty]] -> 10 | G14: =Table1[[#This Row],[Weight per order (g)]]/1000 -> 0.01 | H14: =CEILING(Table1[[#This Row],[Weight per order (Kg)]],0.5) -> 0.5 | I14: =_xlfn.XLOOKUP(Table1[[#This Row],[OrderID]],'Courier company invoice'!B:B,'Courier company invoice'!F:F) -> d | J14: =_xlfn.XLOOKUP(Table1[[#This Row],[OrderID]],Table2[Order ID],Table2[Type of Shipment],"Not Found") -> Forward and RTO charges | K14: =INDEX(Sheet1[],1,MATCH("fwd_"&Table1[[#This Row],[Zone]]&"_fixed",Sheet1[#Headers],0)) -> 45.4 | L14: =INDEX(Sheet1[],1,MATCH("fwd_"&Table1[[#This Row],[Zone]]&"_additional",Sheet1[#Headers],0)) -> 44.8 | M14: =(Table1[[#This Row],[Weight slab]]-0.5)/0.5 -> 0 | N14: =Table1[[#This Row],[Fixed_Charges]]+Table1[[#This Row],[No_of_Extra_slabs]]*Table1[[#This Row],[Additional_Charges]] -> 45.4 | O14: =_xlfn.XLOOKUP(Table1[[#This Row],[OrderID]],'Courier company invoice'!B:B,'Courier company invoice'!H:H) -> 345 | P14: =Table1[[#This Row],[Billing Amount]]-Table1[[#This Row],[Expected charges]] -> 299.6 | Q14: {=_xlfn.IFS(Table1[[#This Row],[Billing Amount]]>Table1[[#This Row],[Expected charges]],"Over Charged",Table1[[#This Row],[Billing Amount]]<Table1[[#This Row],[Expected charges]],"Under Charged",Table1[[#This Row],[Billing Amount]]=Table1[[#This Row],[Expected charges]],"Correctly Charged")} -> Over Charged
A15: 2001823564 | B15: =Table1[[#This Row],[Order ID]]*1 -> 2001823564 | C15: 8904223819291 | D15: 2 | E15: =_xlfn.XLOOKUP(Table1[[#This Row],[SKU (Product Code)]],'SKU Master'!A:A,'SKU Master'!B:B) -> 112 | F15: =Table1[[#This Row],[Product weight]]*Table1[[#This Row],[Order Qty]] -> 224 | G15: =Table1[[#This Row],[Weight per order (g)]]/1000 -> 0.224 | H15: =CEILING(Table1[[#This Row],[Weight per order (Kg)]],0.5) -> 0.5 | I15: =_xlfn.XLOOKUP(Table1[[#This Row],[OrderID]],'Courier company invoice'!B:B,'Courier company invoice'!F:F) -> d | J15: =_xlfn.XLOOKUP(Table1[[#This Row],[OrderID]],Table2[Order ID],Table2[Type of Shipment],"Not Found") -> Forward and RTO charges | K15: =INDEX(Sheet1[],1,MATCH("fwd_"&Table1[[#This Row],[Zone]]&"_fixed",Sheet1[#Headers],0)) -> 45.4 | L15: =INDEX(Sheet1[],1,MATCH("fwd_"&Table1[[#This Row],[Zone]]&"_additional",Sheet1[#Headers],0)) -> 44.8 | M15: =(Table1[[#This Row],[Weight slab]]-0.5)/0.5 -> 0 | N15: =Table1[[#This Row],[Fixed_Charges]]+Table1[[#This Row],[No_of_Extra_slabs]]*Table1[[#This Row],[Additional_Charges]] -> 45.4 | O15: =_xlfn.XLOOKUP(Table1[[#This Row],[OrderID]],'Courier company invoice'!B:B,'Courier company invoice'!H:H) -> 172.8 | P15: =Table1[[#This Row],[Billing Amount]]-Table1[[#This Row],[Expected charges]] -> 127.4 | Q15: {=_xlfn.IFS(Table1[[#This Row],[Billing Amount]]>Table1[[#This Row],[Expected charges]],"Over Charged",Table1[[#This Row],[Billing Amount]]<Table1[[#This Row],[Expected charges]],"Under Charged",Table1[[#This Row],[Billing Amount]]=Table1[[#This Row],[Expected charges]],"Correctly Charged")} -> Over Charged
A16: 2001823564 | B16: =Table1[[#This Row],[Order ID]]*1 -> 2001823564 | C16: 8904223819031 | D16: 2 | E16: =_xlfn.XLOOKUP(Table1[[#This Row],[SKU (Product Code)]],'SKU Master'!A:A,'SKU Master'!B:B) -> 112 | F16: =Table1[[#This Row],[Product weight]]*Table1[[#This Row],[Order Qty]] -> 224 | G16: =Table1[[#This Row],[Weight per order (g)]]/1000 -> 0.224 | H16: =CEILING(Table1[[#This Row],[Weight per order (Kg)]],0.5) -> 0.5 | I16: =_xlfn.XLOOKUP(Table1[[#This Row],[OrderID]],'Courier company invoice'!B:B,'Courier company invoice'!F:F) -> d | J16: =_xlfn.XLOOKUP(Table1[[#This Row],[OrderID]],Table2[Order ID],Table2[Type of Shipment],"Not Found") -> Forward and RTO charges | K16: =INDEX(Sheet1[],1,MATCH("fwd_"&Table1[[#This Row],[Zone]]&"_fixed",Sheet1[#Headers],0)) -> 45.4 | L16: =INDEX(Sheet1[],1,MATCH("fwd_"&Table1[[#This Row],[Zone]]&"_additional",Sheet1[#Headers],0)) -> 44.8 | M16: =(Table1[[#This Row],[Weight slab]]-0.5)/0.5 -> 0 | N16: =Table1[[#This Row],[Fixed_Charges]]+Table1[[#This Row],[No_of_Extra_slabs]]*Table1[[#This Row],[Additional_Charges]] -> 45.4 | O16: =_xlfn.XLOOKUP(Table1[[#This Row],[OrderID]],'Courier company invoice'!B:B,'Courier company invoice'!H:H) -> 172.8 | P16: =Table1[[#This Row],[Billing Amount]]-Table1[[#This Row],[Expected charges]] -> 127.4 | Q16: {=_xlfn.IFS(Table1[[#This Row],[Billing Amount]]>Table1[[#This Row],[Expected charges]],"Over Charged",Table1[[#This Row],[Billing Amount]]<Table1[[#This Row],[Expected charges]],"Under Charged",Table1[[#This Row],[Billing Amount]]=Table1[[#This Row],[Expected charges]],"Correctly Charged")} -> Over Charged
A17: 2001823564 | B17: =Table1[[#This Row],[Order ID]]*1 -> 2001823564 | C17: 8904223819024 | D17: 2 | E17: =_xlfn.XLOOKUP(Table1[[#This Row],[SKU (Product Code)]],'SKU Master'!A:A,'SKU Master'!B:B) -> 112 | F17: =Table1[[#This Row],[Product weight]]*Table1[[#This Row],[Order Qty]] -> 224 | G17: =Table1[[#This Row],[Weight per order (g)]]/1000 -> 0.224 | H17: =CEILING(Table1[[#This Row],[Weight per order (Kg)]],0.5) -> 0.5 | I17: =_xlfn.XLOOKUP(Table1[[#This Row],[OrderID]],'Courier company invoice'!B:B,'Courier company invoice'!F:F) -> d | J17: =_xlfn.XLOOKUP(Table1[[#This Row],[OrderID]],Table2[Order ID],Table2[Type of Shipment],"Not Found") -> Forward and RTO charges | K17: =INDEX(Sheet1[],1,MATCH("fwd_"&Table1[[#This Row],[Zone]]&"_fixed",Sheet1[#Headers],0)) -> 45.4 | L17: =INDEX(Sheet1[],1,MATCH("fwd_"&Table1[[#This Row],[Zone]]&"_additional",Sheet1[#Headers],0)) -> 44.8 | M17: =(Table1[[#This Row],[Weight slab]]-0.5)/0.5 -> 0 | N17: =Table1[[#This Row],[Fixed_Charges]]+Table1[[#This Row],[No_of_Extra_slabs]]*Table1[[#This Row],[Additional_Charges]] -> 45.4 | O17: =_xlfn.XLOOKUP(Table1[[#This Row],[OrderID]],'Courier company invoice'!B:B,'Courier company invoice'!H:H) -> 172.8 | P17: =Table1[[#This Row],[Billing Amount]]-Table1[[#This Row],[Expected charges]] -> 127.4 | Q17: {=_xlfn.IFS(Table1[[#This Row],[Billing Amount]]>Table1[[#This Row],[Expected charges]],"Over Charged",Table1[[#This Row],[Billing Amount]]<Table1[[#This Row],[Expected charges]],"Under Charged",Table1[[#This Row],[Billing Amount]]=Table1[[#This Row],[Expected charges]],"Correctly Charged")} -> Over Charged
A18: 2001822466 | B18: =Table1[[#This Row],[Order ID]]*1 -> 2001822466 | C18: 8904223819468 | D18: 2 | E18: =_xlfn.XLOOKUP(Table1[[#This Row],[SKU (Product Code)]],'SKU Master'!A:A,'SKU Master'!B:B) -> 240 | F18: =Table1[[#This Row],[Product weight]]*Table1[[#This Row],[Order Qty]] -> 480 | G18: =Table1[[#This Row],[Weight per order (g)]]/1000 -> 0.48 | H18: =CEILING(Table1[[#This Row],[Weight per order (Kg)]],0.5) -> 0.5 | I18: =_xlfn.XLOOKUP(Table1[[#This Row],[OrderID]],'Courier company invoice'!B:B,'Courier company invoice'!F:F) -> d | J18: =_xlfn.XLOOKUP(Table1[[#This Row],[OrderID]],Table2[Order ID],Table2[Type of Shipment],"Not Found") -> Forward charges | K18: =INDEX(Sheet1[],1,MATCH("fwd_"&Table1[[#This Row],[Zone]]&"_fixed",Sheet1[#Headers],0)) -> 45.4 | L18: =INDEX(Sheet1[],1,MATCH("fwd_"&Table1[[#This Row],[Zone]]&"_additional",Sheet1[#Headers],0)) -> 44.8 | M18: =(Table1[[#This Row],[Weight slab]]-0.5)/0.5 -> 0 | N18: =Table1[[#This Row],[Fixed_Charges]]+Table1[[#This Row],[No_of_Extra_slabs]]*Table1[[#This Row],[Additional_Charges]] -> 45.4 | O18: =_xlfn.XLOOKUP(Table1[[#This Row],[OrderID]],'Courier company invoice'!B:B,'Courier company invoice'!H:H) -> 135 | P18: =Table1[[#This Row],[Billing Amount]]-Table1[[#This Row],[Expected charges]] -> 89.6 | Q18: {=_xlfn.IFS(Table1[[#This Row],[Billing Amount]]>Table1[[#This Row],[Expected charges]],"Over Charged",Table1[[#This Row],[Billing Amount]]<Table1[[#This Row],[Expected charges]],"Under Charged",Table1[[#This Row],[Billing Amount]]=Table1[[#This Row],[Expected charges]],"Correctly Charged")} -> Over Charged
A19: 2001822466 | B19: =Table1[[#This Row],[Order ID]]*1 -> 2001822466 | C19: 8904223819291 | D19: 8 | E19: =_xlfn.XLOOKUP(Table1[[#This Row],[SKU (Product Code)]],'SKU Master'!A:A,'SKU Master'!B:B) -> 112 | F19: =Table1[[#This Row],[Product weight]]*Table1[[#This Row],[Order Qty]] -> 896 | G19: =Table1[[#This Row],[Weight per order (g)]]/1000 -> 0.896 | H19: =CEILING(Table1[[#This Row],[Weight per order (Kg)]],0.5) -> 1 | I19: =_xlfn.XLOOKUP(Table1[[#This Row],[OrderID]],'Courier company invoice'!B:B,'Courier company invoice'!F:F) -> d | J19: =_xlfn.XLOOKUP(Table1[[#This Row],[OrderID]],Table2[Order ID],Table2[Type of Shipment],"Not Found") -> Forward charges | K19: =INDEX(Sheet1[],1,MATCH("fwd_"&Table1[[#This Row],[Zone]]&"_fixed",Sheet1[#Headers],0)) -> 45.4 | L19: =INDEX(Sheet1[],1,MATCH("fwd_"&Table1[[#This Row],[Zone]]&"_additional",Sheet1[#Headers],0)) -> 44.8 | M19: =(Table1[[#This Row],[Weight slab]]-0.5)/0.5 -> 1 | N19: =Table1[[#This Row],[Fixed_Charges]]+Table1[[#This Row],[No_of_Extra_slabs]]*Table1[[#This Row],[Additional_Charges]] -> 90.2 | O19: =_xlfn.XLOOKUP(Table1[[#This Row],[OrderID]],'Courier company invoice'!B:B,'Courier company invoice'!H:H) -> 135 | P19: =Table1[[#This Row],[Billing Amount]]-Table1[[#This Row],[Expected charges]] -> 44.8 | Q19: {=_xlfn.IFS(Table1[[#This Row],[Billing Amount]]>Table1[[#This Row],[Expected charges]],"Over Charged",Table1[[#This Row],[Billing Amount]]<Table1[[#This Row],[Expected charges]],"Under Charged",Table1[[#This Row],[Billing Amount]]=Table1[[#This Row],[Expected charges]],"Correctly Charged")} -> Over Charged
A20: 2001821995 | B20: =Table1[[#This Row],[Order ID]]*1 -> 2001821995 | C20: 8904223819130 | D20: 1 | E20: =_xlfn.XLOOKUP(Table1[[#This Row],[SKU (Product Code)]],'SKU Master'!A:A,'SKU Master'!B:B) -> 350 | F20: =Table1[[#This Row],[Product weight]]*Table1[[#This Row],[Order Qty]] -> 350 | G20: =Table1[[#This Row],[Weight per order (g)]]/1000 -> 0.35 | H20: =CEILING(Table1[[#This Row],[Weight per order (Kg)]],0.5) -> 0.5 | I20: =_xlfn.XLOOKUP(Table1[[#This Row],[OrderID]],'Courier company invoice'!B:B,'Courier company invoice'!F:F) -> d | J20: =_xlfn.XLOOKUP(Table1[[#This Row],[OrderID]],Table2[Order ID],Table2[Type of Shipment],"Not Found") -> Forward charges | K20: =INDEX(Sheet1[],1,MATCH("fwd_"&Table1[[#This Row],[Zone]]&"_fixed",Sheet1[#Headers],0)) -> 45.4 | L20: =INDEX(Sheet1[],1,MATCH("fwd_"&Table1[[#This Row],[Zone]]&"_additional",Sheet1[#Headers],0)) -> 44.8 | M20: =(Table1[[#This Row],[Weight slab]]-0.5)/0.5 -> 0 | N20: =Table1[[#This Row],[Fixed_Charges]]+Table1[[#This Row],[No_of_Extra_slabs]]*Table1[[#This Row],[Additional_Charges]] -> 45.4 | O20: =_xlfn.XLOOKUP(Table1[[#This Row],[OrderID]],'Courier company invoice'!B:B,'Courier company invoice'!H:H) -> 45.4 | P20: =Table1[[#This Row],[Billing Amount]]-Table1[[#This Row],[Expected charges]] -> 0 | Q20: {=_xlfn.IFS(Table1[[#This Row],[Billing Amount]]>Table1[[#This Row],[Expected charges]],"Over Charged",Table1[[#This Row],[Billing Amount]]<Table1[[#This Row],[Expected charges]],"Under Charged",Table1[[#This Row],[Billing Amount]]=Table1[[#This Row],[Expected charges]],"Correctly Charged")} -> Correctly Charged
A21: 2001821995 | B21: =Table1[[#This Row],[Order ID]]*1 -> 2001821995 | C21: 8904223818706 | D21: 1 | E21: =_xlfn.XLOOKUP(Table1[[#This Row],[SKU (Product Code)]],'SKU Master'!A:A,'SKU Master'!B:B) -> 127 | F21: =Table1[[#This Row],[Product weight]]*Table1[[#This Row],[Order Qty]] -> 127 | G21: =Table1[[#This Row],[Weight per order (g)]]/1000 -> 0.127 | H21: =CEILING(Table1[[#This Row],[Weight per order (Kg)]],0.5) -> 0.5 | I21: =_xlfn.XLOOKUP(Table1[[#This Row],[OrderID]],'Courier company invoice'!B:B,'Courier company invoice'!F:F) -> d | J21: =_xlfn.XLOOKUP(Table1[[#This Row],[OrderID]],Table2[Order ID],Table2[Type of Shipment],"Not Found") -> Forward charges | K21: =INDEX(Sheet1[],1,MATCH("fwd_"&Table1[[#This Row],[Zone]]&"_fixed",Sheet1[#Headers],0)) -> 45.4 | L21: =INDEX(Sheet1[],1,MATCH("fwd_"&Table1[[#This Row],[Zone]]&"_additional",Sheet1[#Headers],0)) -> 44.8 | M21: =(Table1[[#This Row],[Weight slab]]-0.5)/0.5 -> 0 | N21: =Table1[[#This Row],[Fixed_Charges]]+Table1[[#This Row],[No_of_Extra_slabs]]*Table1[[#This Row],[Additional_Charges]] -> 45.4 | O21: =_xlfn.XLOOKUP(Table1[[#This Row],[OrderID]],'Courier company invoice'!B:B,'Courier company invoice'!H:H) -> 45.4 | P21: =Table1[[#This Row],[Billing Amount]]-Table1[[#This Row],[Expected charges]] -> 0 | Q21: {=_xlfn.IFS(Table1[[#This Row],[Billing Amount]]>Table1[[#This Row],[Expected charges]],"Over Charged",Table1[[#This Row],[Billing Amount]]<Table1[[#This Row],[Expected charges]],"Under Charged",Table1[[#This Row],[Billing Amount]]=Table1[[#This Row],[Expected charges]],"Correctly Charged")} -> Correctly Charged
A22: 2001821766 | B22: =Table1[[#This Row],[Order ID]]*1 -> 2001821766 | C22: 8904223818591 | D22: 2 | E22: =_xlfn.XLOOKUP(Table1[[#This Row],[SKU (Product Code)]],'SKU Master'!A:A,'SKU Master'!B:B) -> 120 | F22: =Table1[[#This Row],[Product weight]]*Table1[[#This Row],[Order Qty]] -> 240 | G22: =Table1[[#This Row],[Weight per order (g)]]/1000 -> 0.24 | H22: =CEILING(Table1[[#This Row],[Weight per order (Kg)]],0.5) -> 0.5 | I22: =_xlfn.XLOOKUP(Table1[[#This Row],[OrderID]],'Courier company invoice'!B:B,'Courier company invoice'!F:F) -> d | J22: =_xlfn.XLOOKUP(Table1[[#This Row],[OrderID]],Table2[Order ID],Table2[Type of Shipment],"Not Found") -> Forward charges | K22: =INDEX(Sheet1[],1,MATCH("fwd_"&Table1[[#This Row],[Zone]]&"_fixed",Sheet1[#Headers],0)) -> 45.4 | L22: =INDEX(Sheet1[],1,MATCH("fwd_"&Table1[[#This Row],[Zone]]&"_additional",Sheet1[#Headers],0)) -> 44.8 | M22: =(Table1[[#This Row],[Weight slab]]-0.5)/0.5 -> 0 | N22: =Table1[[#This Row],[Fixed_Charges]]+Table1[[#This Row],[No_of_Extra_slabs]]*Table1[[#This Row],[Additional_Charges]] -> 45.4 | O22: =_xlfn.XLOOKUP(Table1[[#This Row],[OrderID]],'Courier company invoice'!B:B,'Courier company invoice'!H:H) -> 45.4 | P22: =Table1[[#This Row],[Billing Amount]]-Table1[[#This Row],[Expected charges]] -> 0 | Q22: {=_xlfn.IFS(Table1[[#This Row],[Billing Amount]]>Table1[[#This Row],[Expected charges]],"Over Charged",Table1[[#This Row],[Billing Amount]]<Table1[[#This Row],[Expected charges]],"Under Charged",Table1[[#This Row],[Billing Amount]]=Table1[[#This Row],[Expected charges]],"Correctly Charged")} -> Correctly Charged
A23: 2001821750 | B23: =Table1[[#This Row],[Order ID]]*1 -> 2001821750 | C23: 8904223818850 | D23: 1 | E23: =_xlfn.XLOOKUP(Table1[[#This Row],[SKU (Product Code)]],'SKU Master'!A:A,'SKU Master'!B:B) -> 240 | F23: =Table1[[#This Row],[Product weight]]*Table1[[#This Row],[Order Qty]] -> 240 | G23: =Table1[[#This Row],[Weight per order (g)]]/1000 -> 0.24 | H23: =CEILING(Table1[[#This Row],[Weight per order (Kg)]],0.5) -> 0.5 | I23: =_xlfn.XLOOKUP(Table1[[#This Row],[OrderID]],'Courier company invoice'!B:B,'Courier company invoice'!F:F) -> d | J23: =_xlfn.XLOOKUP(Table1[[#This Row],[OrderID]],Table2[Order ID],Table2[Type of Shipment],"Not Found") -> Forward charges | K23: =INDEX(Sheet1[],1,MATCH("fwd_"&Table1[[#This Row],[Zone]]&"_fixed",Sheet1[#Headers],0)) -> 45.4 | L23: =INDEX(Sheet1[],1,MATCH("fwd_"&Table1[[#This Row],[Zone]]&"_additional",Sheet1[#Headers],0)) -> 44.8 | M23: =(Table1[[#This Row],[Weight slab]]-0.5)/0.5 -> 0 | N23: =Table1[[#This Row],[Fixed_Charges]]+Table1[[#This Row],[No_of_Extra_slabs]]*Table1[[#This Row],[Additional_Charges]] -> 45.4 | O23: =_xlfn.XLOOKUP(Table1[[#This Row],[OrderID]],'Courier company invoice'!B:B,'Courier company invoice'!H:H) -> 90.2 | P23: =Table1[[#This Row],[Billing Amount]]-Table1[[#This Row],[Expected charges]] -> 44.8 | Q23: {=_xlfn.IFS(Table1[[#This Row],[Billing Amount]]>Table1[[#This Row],[Expected charges]],"Over Charged",Table1[[#This Row],[Billing Amount]]<Table1[[#This Row],[Expected charges]],"Under Charged",Table1[[#This Row],[Billing Amount]]=Table1[[#This Row],[Expected charges]],"Correctly Charged")} -> Over Charged
A24: 2001821750 | B24: =Table1[[#This Row],[Order ID]]*1 -> 2001821750 | C24: 8904223818430 | D24: 1 | E24: =_xlfn.XLOOKUP(Table1[[#This Row],[SKU (Product Code)]],'SKU Master'!A:A,'SKU Master'!B:B) -> 165 | F24: =Table1[[#This Row],[Product weight]]*Table1[[#This Row],[Order Qty]] -> 165 | G24: =Table1[[#This Row],[Weight per order (g)]]/1000 -> 0.165 | H24: =CEILING(Table1[[#This Row],[Weight per order (Kg)]],0.5) -> 0.5 | I24: =_xlfn.XLOOKUP(Table1[[#This Row],[OrderID]],'Courier company invoice'!B:B,'Courier company invoice'!F:F) -> d | J24: =_xlfn.XLOOKUP(Table1[[#This Row],[OrderID]],Table2[Order ID],Table2[Type of Shipment],"Not Found") -> Forward charges | K24: =INDEX(Sheet1[],1,MATCH("fwd_"&Table1[[#This Row],[Zone]]&"_fixed",Sheet1[#Headers],0)) -> 45.4 | L24: =INDEX(Sheet1[],1,MATCH("fwd_"&Table1[[#This Row],[Zone]]&"_additional",Sheet1[#Headers],0)) -> 44.8 | M24: =(Table1[[#This Row],[Weight slab]]-0.5)/0.5 -> 0 | N24: =Table1[[#This Row],[Fixed_Charges]]+Table1[[#This Row],[No_of_Extra_slabs]]*Table1[[#This Row],[Additional_Charges]] -> 45.4 | O24: =_xlfn.XLOOKUP(Table1[[#This Row],[OrderID]],'Courier company invoice'!B:B,'Courier company invoice'!H:H) -> 90.2 | P24: =Table1[[#This Row],[Billing Amount]]-Table1[[#This Row],[Expected charges]] -> 44.8 | Q24: {=_xlfn.IFS(Table1[[#This Row],[Billing Amount]]>Table1[[#This Row],[Expected charges]],"Over Charged",Table1[[#This Row],[Billing Amount]]<Table1[[#This Row],[Expected charges]],"Under Charged",Table1[[#This Row],[Billing Amount]]=Table1[[#This Row],[Expected charges]],"Correctly Charged")} -> Over Charged
A25: 2001821750 | B25: =Table1[[#This Row],[Order ID]]*1 -> 2001821750 | C25: 8904223819130 | D25: 1 | E25: =_xlfn.XLOOKUP(Table1[[#This Row],[SKU (Product Code)]],'SKU Master'!A:A,'SKU Master'!B:B) -> 350 | F25: =Table1[[#This Row],[Product weight]]*Table1[[#This Row],[Order Qty]] -> 350 | G25: =Table1[[#This Row],[Weight per order (g)]]/1000 -> 0.35 | H25: =CEILING(Table1[[#This Row],[Weight per order (Kg)]],0.5) -> 0.5 | I25: =_xlfn.XLOOKUP(Table1[[#This Row],[OrderID]],'Courier company invoice'!B:B,'Courier company invoice'!F:F) -> d | J25: =_xlfn.XLOOKUP(Table1[[#This Row],[OrderID]],Table2[Order ID],Table2[Type of Shipment],"Not Found") -> Forward charges | K25: =INDEX(Sheet1[],1,MATCH("fwd_"&Table1[[#This Row],[Zone]]&"_fixed",Sheet1[#Headers],0)) -> 45.4 | L25: =INDEX(Sheet1[],1,MATCH("fwd_"&Table1[[#This Row],[Zone]]&"_additional",Sheet1[#Headers],0)) -> 44.8 | M25: =(Table1[[#This Row],[Weight slab]]-0.5)/0.5 -> 0 | N25: =Table1[[#This Row],[Fixed_Charges]]+Table1[[#This Row],[No_of_Extra_slabs]]*Table1[[#This Row],[Additional_Charges]] -> 45.4 | O25: =_xlfn.XLOOKUP(Table1[[#This Row],[OrderID]],'Courier company invoice'!B:B,'Courier company invoice'!H:H) -> 90.2 | P25: =Table1[[#This Row],[Billing Amount]]-Table1[[#This Row],[Expected charges]] -> 44.8 | Q25: {=_xlfn.IFS(Table1[[#This Row],[Billing Amount]]>Table1[[#This Row],[Expected charges]],"Over Charged",Table1[[#This Row],[Billing Amount]]<Table1[[#This Row],[Expected charges]],"Under Charged",Table1[[#This Row],[Billing Amount]]=Table1[[#This Row],[Expected charges]],"Correctly Charged")} -> Over Charged
A26: 2001821742 | B26: =Table1[[#This Row],[Order ID]]*1 -> 2001821742 | C26: 8904223819468 | D26: 1 | E26: =_xlfn.XLOOKUP(Table1[[#This Row],[SKU (Product Code)]],'SKU Master'!A:A,'SKU Master'!B:B) -> 240 | F26: =Table1[[#This Row],[Product weight]]*Table1[[#This Row],[Order Qty]] -> 240 | G26: =Table1[[#This Row],[Weight per order (g)]]/1000 -> 0.24 | H26: =CEILING(Table1[[#This Row],[Weight per order (Kg)]],0.5) -> 0.5 | I26: =_xlfn.XLOOKUP(Table1[[#This Row],[OrderID]],'Courier company invoice'!B:B,'Courier company invoice'!F:F) -> d | J26: =_xlfn.XLOOKUP(Table1[[#This Row],[OrderID]],Table2[Order ID],Table2[Type of Shipment],"Not Found") -> Forward charges | K26: =INDEX(Sheet1[],1,MATCH("fwd_"&Table1[[#This Row],[Zone]]&"_fixed",Sheet1[#Headers],0)) -> 45.4 | L26: =INDEX(Sheet1[],1,MATCH("fwd_"&Table1[[#This Row],[Zone]]&"_additional",Sheet1[#Headers],0)) -> 44.8 | M26: =(Table1[[#This Row],[Weight slab]]-0.5)/0.5 -> 0 | N26: =Table1[[#This Row],[Fixed_Charges]]+Table1[[#This Row],[No_of_Extra_slabs]]*Table1[[#This Row],[Additional_Charges]] -> 45.4 | O26: =_xlfn.XLOOKUP(Table1[[#This Row],[OrderID]],'Courier company invoice'!B:B,'Courier company invoice'!H:H) -> 45.4 | P26: =Table1[[#This Row],[Billing Amount]]-Table1[[#This Row],[Expected charges]] -> 0 | Q26: {=_xlfn.IFS(Table1[[#This Row],[Billing Amount]]>Table1[[#This Row],[Expected charges]],"Over Charged",Table1[[#This Row],[Billing Amount]]<Table1[[#This Row],[Expected charges]],"Under Charged",Table1[[#This Row],[Billing Amount]]=Table1[[#This Row],[Expected charges]],"Correctly Charged")} -> Correctly Charged
... A47: 2001819252 | B47: =Table1[[#This Row],[Order ID]]*1 -> 2001819252 | C47: 8904223818706 | D47: 1 | E47: =_xlfn.XLOOKUP(Table1[[#This Row],[SKU (Product Code)]],'SKU Master'!A:A,'SKU Master'!B:B) -> 127 | F47: =Table1[[#This Row],[Product weight]]*Table1[[#This Row],[Order Qty]] -> 127 | G47: =Table1[[#This Row],[Weight per order (g)]]/1000 -> 0.127 | H47: =CEILING(Table1[[#This Row],[Weight per order (Kg)]],0.5) -> 0.5 | I47: =_xlfn.XLOOKUP(Table1[[#This Row],[OrderID]],'Courier company invoice'!B:B,'Courier company invoice'!F:F) -> b | J47: =_xlfn.XLOOKUP(Table1[[#This Row],[OrderID]],Table2[Order ID],Table2[Type of Shipment],"Not Found") -> Forward charges | K47: =INDEX(Sheet1[],1,MATCH("fwd_"&Table1[[#This Row],[Zone]]&"_fixed",Sheet1[#Headers],0)) -> 33 | L47: =INDEX(Sheet1[],1,MATCH("fwd_"&Table1[[#This Row],[Zone]]&"_additional",Sheet1[#Headers],0)) -> 28.3 | M47: =(Table1[[#This Row],[Weight slab]]-0.5)/0.5 -> 0 | N47: =Table1[[#This Row],[Fixed_Charges]]+Table1[[#This Row],[No_of_Extra_slabs]]*Table1[[#This Row],[Additional_Charges]] -> 33 | O47: =_xlfn.XLOOKUP(Table1[[#This Row],[OrderID]],'Courier company invoice'!B:B,'Courier company invoice'!H:H) -> 33 | P47: =Table1[[#This Row],[Billing Amount]]-Table1[[#This Row],[Expected charges]] -> 0 | Q47: {=_xlfn.IFS(Table1[[#This Row],[Billing Amount]]>Table1[[#This Row],[Expected charges]],"Over Charged",Table1[[#This Row],[Billing Amount]]<Table1[[#This Row],[Expected charges]],"Under Charged",Table1[[#This Row],[Billing Amount]]=Table1[[#This Row],[Expected charges]],"Correctly Charged")} -> Correctly Charged
A48: 2001819252 | B48: =Table1[[#This Row],[Order ID]]*1 -> 2001819252 | C48: SACHETS001 | D48: 1 | E48: =_xlfn.XLOOKUP(Table1[[#This Row],[SKU (Product Code)]],'SKU Master'!A:A,'SKU Master'!B:B) -> 10 | F48: =Table1[[#This Row],[Product weight]]*Table1[[#This Row],[Order Qty]] -> 10 | G48: =Table1[[#This Row],[Weight per order (g)]]/1000 -> 0.01 | H48: =CEILING(Table1[[#This Row],[Weight per order (Kg)]],0.5) -> 0.5 | I48: =_xlfn.XLOOKUP(Table1[[#This Row],[OrderID]],'Courier company invoice'!B:B,'Courier company invoice'!F:F) -> b | J48: =_xlfn.XLOOKUP(Table1[[#This Row],[OrderID]],Table2[Order ID],Table2[Type of Shipment],"Not Found") -> Forward charges | K48: =INDEX(Sheet1[],1,MATCH("fwd_"&Table1[[#This Row],[Zone]]&"_fixed",Sheet1[#Headers],0)) -> 33 | L48: =INDEX(Sheet1[],1,MATCH("fwd_"&Table1[[#This Row],[Zone]]&"_additional",Sheet1[#Headers],0)) -> 28.3 | M48: =(Table1[[#This Row],[Weight slab]]-0.5)/0.5 -> 0 | N48: =Table1[[#This Row],[Fixed_Charges]]+Table1[[#This Row],[No_of_Extra_slabs]]*Table1[[#This Row],[Additional_Charges]] -> 33 | O48: =_xlfn.XLOOKUP(Table1[[#This Row],[OrderID]],'Courier company invoice'!B:B,'Courier company invoice'!H:H) -> 33 | P48: =Table1[[#This Row],[Billing Amount]]-Table1[[#This Row],[Expected charges]] -> 0 | Q48: {=_xlfn.IFS(Table1[[#This Row],[Billing Amount]]>Table1[[#This Row],[Expected charges]],"Over Charged",Table1[[#This Row],[Billing Amount]]<Table1[[#This Row],[Expected charges]],"Under Charged",Table1[[#This Row],[Billing Amount]]=Table1[[#This Row],[Expected charges]],"Correctly Charged")} -> Correctly Charged
A49: 2001818390 | B49: =Table1[[#This Row],[Order ID]]*1 -> 2001818390 | C49: 8904223819147 | D49: 1 | E49: =_xlfn.XLOOKUP(Table1[[#This Row],[SKU (Product Code)]],'SKU Master'!A:A,'SKU Master'!B:B) -> 240 | F49: =Table1[[#This Row],[Product weight]]*Table1[[#This Row],[Order Qty]] -> 240 | G49: =Table1[[#This Row],[Weight per order (g)]]/1000 -> 0.24 | H49: =CEILING(Table1[[#This Row],[Weight per order (Kg)]],0.5) -> 0.5 | I49: =_xlfn.XLOOKUP(Table1[[#This Row],[OrderID]],'Courier company invoice'!B:B,'Courier company invoice'!F:F) -> e | J49: =_xlfn.XLOOKUP(Table1[[#This Row],[OrderID]],Table2[Order ID],Table2[Type of Shipment],"Not Found") -> Forward and RTO charges | K49: =INDEX(Sheet1[],1,MATCH("fwd_"&Table1[[#This Row],[Zone]]&"_fixed",Sheet1[#Headers],0)) -> 56.6 | L49: =INDEX(Sheet1[],1,MATCH("fwd_"&Table1[[#This Row],[Zone]]&"_additional",Sheet1[#Headers],0)) -> 55.5 | M49: =(Table1[[#This Row],[Weight slab]]-0.5)/0.5 -> 0 | N49: =Table1[[#This Row],[Fixed_Charges]]+Table1[[#This Row],[No_of_Extra_slabs]]*Table1[[#This Row],[Additional_Charges]] -> 56.6 | O49: =_xlfn.XLOOKUP(Table1[[#This Row],[OrderID]],'Courier company invoice'!B:B,'Courier company invoice'!H:H) -> 213.5 | P49: =Table1[[#This Row],[Billing Amount]]-Table1[[#This Row],[Expected charges]] -> 156.9 | Q49: {=_xlfn.IFS(Table1[[#This Row],[Billing Amount]]>Table1[[#This Row],[Expected charges]],"Over Charged",Table1[[#This Row],[Billing Amount]]<Table1[[#This Row],[Expected charges]],"Under Charged",Table1[[#This Row],[Billing Amount]]=Table1[[#This Row],[Expected charges]],"Correctly Charged")} -> Over Charged
A50: 2001818390 | B50: =Table1[[#This Row],[Order ID]]*1 -> 2001818390 | C50: 8904223818935 | D50: 4 | E50: =_xlfn.XLOOKUP(Table1[[#This Row],[SKU (Product Code)]],'SKU Master'!A:A,'SKU Master'!B:B) -> 120 | F50: =Table1[[#This Row],[Product weight]]*Table1[[#This Row],[Order Qty]] -> 480 | G50: =Table1[[#This Row],[Weight per order (g)]]/1000 -> 0.48 | H50: =CEILING(Table1[[#This Row],[Weight per order (Kg)]],0.5) -> 0.5 | I50: =_xlfn.XLOOKUP(Table1[[#This Row],[OrderID]],'Courier company invoice'!B:B,'Courier company invoice'!F:F) -> e | J50: =_xlfn.XLOOKUP(Table1[[#This Row],[OrderID]],Table2[Order ID],Table2[Type of Shipment],"Not Found") -> Forward and RTO charges | K50: =INDEX(Sheet1[],1,MATCH("fwd_"&Table1[[#This Row],[Zone]]&"_fixed",Sheet1[#Headers],0)) -> 56.6 | L50: =INDEX(Sheet1[],1,MATCH("fwd_"&Table1[[#This Row],[Zone]]&"_additional",Sheet1[#Headers],0)) -> 55.5 | M50: =(Table1[[#This Row],[Weight slab]]-0.5)/0.5 -> 0 | N50: =Table1[[#This Row],[Fixed_Charges]]+Table1[[#This Row],[No_of_Extra_slabs]]*Table1[[#This Row],[Additional_Charges]] -> 56.6 | O50: =_xlfn.XLOOKUP(Table1[[#This Row],[OrderID]],'Courier company invoice'!B:B,'Courier company invoice'!H:H) -> 213.5 | P50: =Table1[[#This Row],[Billing Amount]]-Table1[[#This Row],[Expected charges]] -> 156.9 | Q50: {=_xlfn.IFS(Table1[[#This Row],[Billing Amount]]>Table1[[#This Row],[Expected charges]],"Over Charged",Table1[[#This Row],[Billing Amount]]<Table1[[#This Row],[Expected charges]],"Under Charged",Table1[[#This Row],[Billing Amount]]=Table1[[#This Row],[Expected charges]],"Correctly Charged")} -> Over Charged
A51: 2001818390 | B51: =Table1[[#This Row],[Order ID]]*1 -> 2001818390 | C51: 8904223818683 | D51: 1 | E51: =_xlfn.XLOOKUP(Table1[[#This Row],[SKU (Product Code)]],'SKU Master'!A:A,'SKU Master'!B:B) -> 121 | F51: =Table1[[#This Row],[Product weight]]*Table1[[#This Row],[Order Qty]] -> 121 | G51: =Table1[[#This Row],[Weight per order (g)]]/1000 -> 0.121 | H51: =CEILING(Table1[[#This Row],[Weight per order (Kg)]],0.5) -> 0.5 | I51: =_xlfn.XLOOKUP(Table1[[#This Row],[OrderID]],'Courier company invoice'!B:B,'Courier company invoice'!F:F) -> e | J51: =_xlfn.XLOOKUP(Table1[[#This Row],[OrderID]],Table2[Order ID],Table2[Type of Shipment],"Not Found") -> Forward and RTO charges | K51: =INDEX(Sheet1[],1,MATCH("fwd_"&Table1[[#This Row],[Zone]]&"_fixed",Sheet1[#Headers],0)) -> 56.6 | L51: =INDEX(Sheet1[],1,MATCH("fwd_"&Table1[[#This Row],[Zone]]&"_additional",Sheet1[#Headers],0)) -> 55.5 | M51: =(Table1[[#This Row],[Weight slab]]-0.5)/0.5 -> 0 | N51: =Table1[[#This Row],[Fixed_Charges]]+Table1[[#This Row],[No_of_Extra_slabs]]*Table1[[#This Row],[Additional_Charges]] -> 56.6 | O51: =_xlfn.XLOOKUP(Table1[[#This Row],[OrderID]],'Courier company invoice'!B:B,'Courier company invoice'!H:H) -> 213.5 | P51: =Table1[[#This Row],[Billing Amount]]-Table1[[#This Row],[Expected charges]] -> 156.9 | Q51: {=_xlfn.IFS(Table1[[#This Row],[Billing Amount]]>Table1[[#This Row],[Expected charges]],"Over Charged",Table1[[#This Row],[Billing Amount]]<Table1[[#This Row],[Expected charges]],"Under Charged",Table1[[#This Row],[Billing Amount]]=Table1[[#This Row],[Expected charges]],"Correctly Charged")} -> Over Charged
A52: 2001817160 | B52: =Table1[[#This Row],[Order ID]]*1 -> 2001817160 | C52: 8904223818478 | D52: 1 | E52: =_xlfn.XLOOKUP(Table1[[#This Row],[SKU (Product Code)]],'SKU Master'!A:A,'SKU Master'!B:B) -> 350 | F52: =Table1[[#This Row],[Product weight]]*Table1[[#This Row],[Order Qty]] -> 350 | G52: =Table1[[#This Row],[Weight per order (g)]]/1000 -> 0.35 | H52: =CEILING(Table1[[#This Row],[Weight per order (Kg)]],0.5) -> 0.5 | I52: =_xlfn.XLOOKUP(Table1[[#This Row],[OrderID]],'Courier company invoice'!B:B,'Courier company invoice'!F:F) -> d | J52: =_xlfn.XLOOKUP(Table1[[#This Row],[OrderID]],Table2[Order ID],Table2[Type of Shipment],"Not Found") -> Forward and RTO charges | K52: =INDEX(Sheet1[],1,MATCH("fwd_"&Table1[[#This Row],[Zone]]&"_fixed",Sheet1[#Headers],0)) -> 45.4 | L52: =INDEX(Sheet1[],1,MATCH("fwd_"&Table1[[#This Row],[Zone]]&"_additional",Sheet1[#Headers],0)) -> 44.8 | M52: =(Table1[[#This Row],[Weight slab]]-0.5)/0.5 -> 0 | N52: =Table1[[#This Row],[Fixed_Charges]]+Table1[[#This Row],[No_of_Extra_slabs]]*Table1[[#This Row],[Additional_Charges]] -> 45.4 | O52: =_xlfn.XLOOKUP(Table1[[#This Row],[OrderID]],'Courier company invoice'!B:B,'Courier company invoice'!H:H) -> 172.8 | P52: =Table1[[#This Row],[Billing Amount]]-Table1[[#This Row],[Expected charges]] -> 127.4 | Q52: {=_xlfn.IFS(Table1[[#This Row],[Billing Amount]]>Table1[[#This Row],[Expected charges]],"Over Charged",Table1[[#This Row],[Billing Amount]]<Table1[[#This Row],[Expected charges]],"Under Charged",Table1[[#This Row],[Billing Amount]]=Table1[[#This Row],[Expected charges]],"Correctly Charged")} -> Over Charged
A53: 2001817160 | B53: =Table1[[#This Row],[Order ID]]*1 -> 2001817160 | C53: 8904223819284 | D53: 1 | E53: =_xlfn.XLOOKUP(Table1[[#This Row],[SKU (Product Code)]],'SKU Master'!A:A,'SKU Master'!B:B) -> 350 | F53: =Table1[[#This Row],[Product weight]]*Table1[[#This Row],[Order Qty]] -> 350 | G53: =Table1[[#This Row],[Weight per order (g)]]/1000 -> 0.35 | H53: =CEILING(Table1[[#This Row],[Weight per order (Kg)]],0.5) -> 0.5 | I53: =_xlfn.XLOOKUP(Table1[[#This Row],[OrderID]],'Courier company invoice'!B:B,'Courier company invoice'!F:F) -> d | J53: =_xlfn.XLOOKUP(Table1[[#This Row],[OrderID]],Table2[Order ID],Table2[Type of Shipment],"Not Found") -> Forward and RTO charges | K53: =INDEX(Sheet1[],1,MATCH("fwd_"&Table1[[#This Row],[Zone]]&"_fixed",Sheet1[#Headers],0)) -> 45.4 | L53: =INDEX(Sheet1[],1,MATCH("fwd_"&Table1[[#This Row],[Zone]]&"_additional",Sheet1[#Headers],0)) -> 44.8 | M53: =(Table1[[#This Row],[Weight slab]]-0.5)/0.5 -> 0 | N53: =Table1[[#This Row],[Fixed_Charges]]+Table1[[#This Row],[No_of_Extra_slabs]]*Table1[[#This Row],[Additional_Charges]] -> 45.4 | O53: =_xlfn.XLOOKUP(Table1[[#This Row],[OrderID]],'Courier company invoice'!B:B,'Courier company invoice'!H:H) -> 172.8 | P53: =Table1[[#This Row],[Billing Amount]]-Table1[[#This Row],[Expected charges]] -> 127.4 | Q53: {=_xlfn.IFS(Table1[[#This Row],[Billing Amount]]>Table1[[#This Row],[Expected charges]],"Over Charged",Table1[[#This Row],[Billing Amount]]<Table1[[#This Row],[Expected charges]],"Under Charged",Table1[[#This Row],[Billing Amount]]=Table1[[#This Row],[Expected charges]],"Correctly Charged")} -> Over Charged
A54: 2001817093 | B54: =Table1[[#This Row],[Order ID]]*1 -> 2001817093 | C54: 8904223816214 | D54: 1 | E54: =_xlfn.XLOOKUP(Table1[[#This Row],[SKU (Product Code)]],'SKU Master'!A:A,'SKU Master'!B:B) -> 120 | F54: =Table1[[#This Row],[Product weight]]*Table1[[#This Row],[Order Qty]] -> 120 | G54: =Table1[[#This Row],[Weight per order (g)]]/1000 -> 0.12 | H54: =CEILING(Table1[[#This Row],[Weight per order (Kg)]],0.5) -> 0.5 | I54: =_xlfn.XLOOKUP(Table1[[#This Row],[OrderID]],'Courier company invoice'!B:B,'Courier company invoice'!F:F) -> b | J54: =_xlfn.XLOOKUP(Table1[[#This Row],[OrderID]],Table2[Order ID],Table2[Type of Shipment],"Not Found") -> Forward and RTO charges | K54: =INDEX(Sheet1[],1,MATCH("fwd_"&Table1[[#This Row],[Zone]]&"_fixed",Sheet1[#Headers],0)) -> 33 | L54: =INDEX(Sheet1[],1,MATCH("fwd_"&Table1[[#This Row],[Zone]]&"_additional",Sheet1[#Headers],0)) -> 28.3 | M54: =(Table1[[#This Row],[Weight slab]]-0.5)/0.5 -> 0 | N54: =Table1[[#This Row],[Fixed_Charges]]+Table1[[#This Row],[No_of_Extra_slabs]]*Table1[[#This Row],[Additional_Charges]] -> 33 | O54: =_xlfn.XLOOKUP(Table1[[#This Row],[OrderID]],'Courier company invoice'!B:B,'Courier company invoice'!H:H) -> 151.1 | P54: =Table1[[#This Row],[Billing Amount]]-Table1[[#This Row],[Expected charges]] -> 118.1 | Q54: {=_xlfn.IFS(Table1[[#This Row],[Billing Amount]]>Table1[[#This Row],[Expected charges]],"Over Charged",Table1[[#This Row],[Billing Amount]]<Table1[[#This Row],[Expected charges]],"Under Charged",Table1[[#This Row],[Billing Amount]]=Table1[[#This Row],[Expected charges]],"Correctly Charged")} -> Over Charged
A55: 2001817093 | B55: =Table1[[#This Row],[Order ID]]*1 -> 2001817093 | C55: 8904223818874 | D55: 1 | E55: =_xlfn.XLOOKUP(Table1[[#This Row],[SKU (Product Code)]],'SKU Master'!A:A,'SKU Master'!B:B) -> 100 | F55: =Table1[[#This Row],[Product weight]]*Table1[[#This Row],[Order Qty]] -> 100 | G55: =Table1[[#This Row],[Weight per order (g)]]/1000 -> 0.1 | H55: =CEILING(Table1[[#This Row],[Weight per order (Kg)]],0.5) -> 0.5 | I55: =_xlfn.XLOOKUP(Table1[[#This Row],[OrderID]],'Courier company invoice'!B:B,'Courier company invoice'!F:F) -> b | J55: =_xlfn.XLOOKUP(Table1[[#This Row],[OrderID]],Table2[Order ID],Table2[Type of Shipment],"Not Found") -> Forward and RTO charges | K55: =INDEX(Sheet1[],1,MATCH("fwd_"&Table1[[#This Row],[Zone]]&"_fixed",Sheet1[#Headers],0)) -> 33 | L55: =INDEX(Sheet1[],1,MATCH("fwd_"&Table1[[#This Row],[Zone]]&"_additional",Sheet1[#Headers],0)) -> 28.3 | M55: =(Table1[[#This Row],[Weight slab]]-0.5)/0.5 -> 0 | N55: =Table1[[#This Row],[Fixed_Charges]]+Table1[[#This Row],[No_of_Extra_slabs]]*Table1[[#This Row],[Additional_Charges]] -> 33 | O55: =_xlfn.XLOOKUP(Table1[[#This Row],[OrderID]],'Courier company invoice'!B:B,'Courier company invoice'!H:H) -> 151.1 | P55: =Table1[[#This Row],[Billing Amount]]-Table1[[#This Row],[Expected charges]] -> 118.1 | Q55: {=_xlfn.IFS(Table1[[#This Row],[Billing Amount]]>Table1[[#This Row],[Expected charges]],"Over Charged",Table1[[#This Row],[Billing Amount]]<Table1[[#This Row],[Expected charges]],"Under Charged",Table1[[#This Row],[Billing Amount]]=Table1[[#This Row],[Expected charges]],"Correctly Charged")} -> Over Charged
A56: 2001817093 | B56: =Table1[[#This Row],[Order ID]]*1 -> 2001817093 | C56: 8904223819512 | D56: 1 | E56: =_xlfn.XLOOKUP(Table1[[#This Row],[SKU (Product Code)]],'SKU Master'!A:A,'SKU Master'!B:B) -> 210 | F56: =Table1[[#This Row],[Product weight]]*Table1[[#This Row],[Order Qty]] -> 210 | G56: =Table1[[#This Row],[Weight per order (g)]]/1000 -> 0.21 | H56: =CEILING(Table1[[#This Row],[Weight per order (Kg)]],0.5) -> 0.5 | I56: =_xlfn.XLOOKUP(Table1[[#This Row],[OrderID]],'Courier company invoice'!B:B,'Courier company invoice'!F:F) -> b | J56: =_xlfn.XLOOKUP(Table1[[#This Row],[OrderID]],Table2[Order ID],Table2[Type of Shipment],"Not Found") -> Forward and RTO charges | K56: =INDEX(Sheet1[],1,MATCH("fwd_"&Table1[[#This Row],[Zone]]&"_fixed",Sheet1[#Headers],0)) -> 33 | L56: =INDEX(Sheet1[],1,MATCH("fwd_"&Table1[[#This Row],[Zone]]&"_additional",Sheet1[#Headers],0)) -> 28.3 | M56: =(Table1[[#This Row],[Weight slab]]-0.5)/0.5 -> 0 | N56: =Table1[[#This Row],[Fixed_Charges]]+Table1[[#This Row],[No_of_Extra_slabs]]*Table1[[#This Row],[Additional_Charges]] -> 33 | O56: =_xlfn.XLOOKUP(Table1[[#This Row],[OrderID]],'Courier company invoice'!B:B,'Courier company invoice'!H:H) -> 151.1 | P56: =Table1[[#This Row],[Billing Amount]]-Table1[[#This Row],[Expected charges]] -> 118.1 | Q56: {=_xlfn.IFS(Table1[[#This Row],[Billing Amount]]>Table1[[#This Row],[Expected charges]],"Over Charged",Table1[[#This Row],[Billing Amount]]<Table1[[#This Row],[Expected charges]],"Under Charged",Table1[[#This Row],[Billing Amount]]=Table1[[#This Row],[Expected charges]],"Correctly Charged")} -> Over Charged
A57: 2001817093 | B57: =Table1[[#This Row],[Order ID]]*1 -> 2001817093 | C57: 8904223818881 | D57: 1 | E57: =_xlfn.XLOOKUP(Table1[[#This Row],[SKU (Product Code)]],'SKU Master'!A:A,'SKU Master'!B:B) -> 140 | F57: =Table1[[#This Row],[Product weight]]*Table1[[#This Row],[Order Qty]] -> 140 | G57: =Table1[[#This Row],[Weight per order (g)]]/1000 -> 0.14 | H57: =CEILING(Table1[[#This Row],[Weight per order (Kg)]],0.5) -> 0.5 | I57: =_xlfn.XLOOKUP(Table1[[#This Row],[OrderID]],'Courier company invoice'!B:B,'Courier company invoice'!F:F) -> b | J57: =_xlfn.XLOOKUP(Table1[[#This Row],[OrderID]],Table2[Order ID],Table2[Type of Shipment],"Not Found") -> Forward and RTO charges | K57: =INDEX(Sheet1[],1,MATCH("fwd_"&Table1[[#This Row],[Zone]]&"_fixed",Sheet1[#Headers],0)) -> 33 | L57: =INDEX(Sheet1[],1,MATCH("fwd_"&Table1[[#This Row],[Zone]]&"_additional",Sheet1[#Headers],0)) -> 28.3 | M57: =(Table1[[#This Row],[Weight slab]]-0.5)/0.5 -> 0 | N57: =Table1[[#This Row],[Fixed_Charges]]+Table1[[#This Row],[No_of_Extra_slabs]]*Table1[[#This Row],[Additional_Charges]] -> 33 | O57: =_xlfn.XLOOKUP(Table1[[#This Row],[OrderID]],'Courier company invoice'!B:B,'Courier company invoice'!H:H) -> 151.1 | P57: =Table1[[#This Row],[Billing Amount]]-Table1[[#This Row],[Expected charges]] -> 118.1 | Q57: {=_xlfn.IFS(Table1[[#This Row],[Billing Amount]]>Table1[[#This Row],[Expected charges]],"Over Charged",Table1[[#This Row],[Billing Amount]]<Table1[[#This Row],[Expected charges]],"Under Charged",Table1[[#This Row],[Billing Amount]]=Table1[[#This Row],[Expected charges]],"Correctly Charged")} -> Over Charged
A58: 2001817093 | B58: =Table1[[#This Row],[Order ID]]*1 -> 2001817093 | C58: 8904223819291 | D58: 2 | E58: =_xlfn.XLOOKUP(Table1[[#This Row],[SKU (Product Code)]],'SKU Master'!A:A,'SKU Master'!B:B) -> 112 | F58: =Table1[[#This Row],[Product weight]]*Table1[[#This Row],[Order Qty]] -> 224 | G58: =Table1[[#This Row],[Weight per order (g)]]/1000 -> 0.224 | H58: =CEILING(Table1[[#This Row],[Weight per order (Kg)]],0.5) -> 0.5 | I58: =_xlfn.XLOOKUP(Table1[[#This Row],[OrderID]],'Courier company invoice'!B:B,'Courier company invoice'!F:F) -> b | J58: =_xlfn.XLOOKUP(Table1[[#This Row],[OrderID]],Table2[Order ID],Table2[Type of Shipment],"Not Found") -> Forward and RTO charges | K58: =INDEX(Sheet1[],1,MATCH("fwd_"&Table1[[#This Row],[Zone]]&"_fixed",Sheet1[#Headers],0)) -> 33 | L58: =INDEX(Sheet1[],1,MATCH("fwd_"&Table1[[#This Row],[Zone]]&"_additional",Sheet1[#Headers],0)) -> 28.3 | M58: =(Table1[[#This Row],[Weight slab]]-0.5)/0.5 -> 0 | N58: =Table1[[#This Row],[Fixed_Charges]]+Table1[[#This Row],[No_of_Extra_slabs]]*Table1[[#This Row],[Additional_Charges]] -> 33 | O58: =_xlfn.XLOOKUP(Table1[[#This Row],[OrderID]],'Courier company invoice'!B:B,'Courier company invoice'!H:H) -> 151.1 | P58: =Table1[[#This Row],[Billing Amount]]-Table1[[#This Row],[Expected charges]] -> 118.1 | Q58: {=_xlfn.IFS(Table1[[#This Row],[Billing Amount]]>Table1[[#This Row],[Expected charges]],"Over Charged",Table1[[#This Row],[Billing Amount]]<Table1[[#This Row],[Expected charges]],"Under Charged",Table1[[#This Row],[Billing Amount]]=Table1[[#This Row],[Expected charges]],"Correctly Charged")} -> Over Charged
